[2025-06-01 11:01:47] Episódio: https://www.youtube.com/watch?v=udilUEZZ17s
Traceback (most recent call last):
  File "C:\Users\vidal\Documents\podcast_cuts/main.py", line 76, in <module>
    run(episode_url)
  File "C:\Users\vidal\Documents\podcast_cuts/main.py", line 48, in run
    thumb_path = thumbnail.gen_thumbnail(h["hook"])
  File "C:\Users\vidal\Documents\podcast_cuts\modules\thumbnail.py", line 10, in gen_thumbnail
    response = call_llm(
  File "C:\Users\vidal\Documents\podcast_cuts\modules\llm_utils.py", line 81, in call_llm
    response = client.images.generate(
  File "c:\Users\vidal\Documents\podcast_cuts\venv\lib\site-packages\openai\resources\images.py", line 322, in generate
    return self._post(
  File "c:\Users\vidal\Documents\podcast_cuts\venv\lib\site-packages\openai\_base_client.py", line 1239, in post
    return cast(ResponseT, self.request(cast_to, opts, stream=stream, stream_cls=stream_cls))
  File "c:\Users\vidal\Documents\podcast_cuts\venv\lib\site-packages\openai\_base_client.py", line 1034, in request
    raise self._make_status_error_from_response(err.response) from None
openai.BadRequestError: Error code: 400 - {'error': {'message': "Invalid value: 'gpt-4o'. Supported values are: 'gpt-image-1', 'dall-e-2', and 'dall-e-3'.", 'type': 'invalid_request_error', 'param': 'model', 'code': 'invalid_value'}}

------------------------------------------------------------
[2025-06-01 11:09:13] Episódio: https://www.youtube.com/watch?v=udilUEZZ17s
Traceback (most recent call last):
  File "C:\Users\vidal\Documents\podcast_cuts/main.py", line 76, in <module>
    run(episode_url)
  File "C:\Users\vidal\Documents\podcast_cuts/main.py", line 48, in run
    thumb_path = thumbnail.gen_thumbnail(h["hook"])
  File "C:\Users\vidal\Documents\podcast_cuts\modules\thumbnail.py", line 10, in gen_thumbnail
    response = call_llm(
  File "C:\Users\vidal\Documents\podcast_cuts\modules\llm_utils.py", line 81, in call_llm
    response = client.images.generate(
  File "c:\Users\vidal\Documents\podcast_cuts\venv\lib\site-packages\openai\resources\images.py", line 322, in generate
    return self._post(
  File "c:\Users\vidal\Documents\podcast_cuts\venv\lib\site-packages\openai\_base_client.py", line 1239, in post
    return cast(ResponseT, self.request(cast_to, opts, stream=stream, stream_cls=stream_cls))
  File "c:\Users\vidal\Documents\podcast_cuts\venv\lib\site-packages\openai\_base_client.py", line 1034, in request
    raise self._make_status_error_from_response(err.response) from None
openai.BadRequestError: Error code: 400 - {'error': {'message': "Invalid value: 'gpt-4o'. Supported values are: 'gpt-image-1', 'dall-e-2', and 'dall-e-3'.", 'type': 'invalid_request_error', 'param': 'model', 'code': 'invalid_value'}}

------------------------------------------------------------
